Traceback (most recent call last):
  File "/home/stephan/miniconda3/envs/jupyterbook/lib/python3.11/site-packages/jupyter_cache/executors/utils.py", line 58, in single_nb_execution
    executenb(
  File "/home/stephan/miniconda3/envs/jupyterbook/lib/python3.11/site-packages/nbclient/client.py", line 1305, in execute
    return NotebookClient(nb=nb, resources=resources, km=km, **kwargs).execute()
           ^^^^^^^^^^^^^^^^^^^^^^^^^^^^^^^^^^^^^^^^^^^^^^^^^^^^^^^^^^^^^^^^^^^^^
  File "/home/stephan/miniconda3/envs/jupyterbook/lib/python3.11/site-packages/jupyter_core/utils/__init__.py", line 166, in wrapped
    return loop.run_until_complete(inner)
           ^^^^^^^^^^^^^^^^^^^^^^^^^^^^^^
  File "/home/stephan/miniconda3/envs/jupyterbook/lib/python3.11/asyncio/base_events.py", line 653, in run_until_complete
    return future.result()
           ^^^^^^^^^^^^^^^
  File "/home/stephan/miniconda3/envs/jupyterbook/lib/python3.11/site-packages/nbclient/client.py", line 705, in async_execute
    await self.async_execute_cell(
  File "/home/stephan/miniconda3/envs/jupyterbook/lib/python3.11/site-packages/nbclient/client.py", line 1058, in async_execute_cell
    await self._check_raise_for_error(cell, cell_index, exec_reply)
  File "/home/stephan/miniconda3/envs/jupyterbook/lib/python3.11/site-packages/nbclient/client.py", line 914, in _check_raise_for_error
    raise CellExecutionError.from_cell_and_msg(cell, exec_reply_content)
nbclient.exceptions.CellExecutionError: An error occurred while executing the following cell:
------------------
#@title
import pandas as pd
import plotly.express as px
import seaborn as sns
import matplotlib.pyplot as plt
import plotly.graph_objs as go
import plotly.express as px
import numpy as np
import shapely
import geopandas as gpd
import folium
from plotly.subplots import make_subplots

import base64

images_path = 'content/'
data_path = 'data/'

# images_path = '/content/drive/MyDrive/VizWiz/'
# data_path = '/content/drive/MyDrive/VizWiz/'

image_path = images_path + 'schiphol.jpg'

with open(image_path, 'rb') as file:
    image_data = file.read()
    image_base64 = base64.b64encode(image_data).decode('utf-8')

from IPython.display import display, HTML
from PIL import Image
import matplotlib.pyplot as plt
------------------


[0;31m---------------------------------------------------------------------------[0m
[0;31mModuleNotFoundError[0m                       Traceback (most recent call last)
Cell [0;32mIn[1], line 9[0m
[1;32m      7[0m [38;5;28;01mimport[39;00m [38;5;21;01mplotly[39;00m[38;5;21;01m.[39;00m[38;5;21;01mexpress[39;00m [38;5;28;01mas[39;00m [38;5;21;01mpx[39;00m
[1;32m      8[0m [38;5;28;01mimport[39;00m [38;5;21;01mnumpy[39;00m [38;5;28;01mas[39;00m [38;5;21;01mnp[39;00m
[0;32m----> 9[0m [38;5;28;01mimport[39;00m [38;5;21;01mshapely[39;00m
[1;32m     10[0m [38;5;28;01mimport[39;00m [38;5;21;01mgeopandas[39;00m [38;5;28;01mas[39;00m [38;5;21;01mgpd[39;00m
[1;32m     11[0m [38;5;28;01mimport[39;00m [38;5;21;01mfolium[39;00m

[0;31mModuleNotFoundError[0m: No module named 'shapely'

